{"original_position": 31, "diff_hunk": "@@ -114,3 +116,24 @@ def test_recipe_api_is_json(conf, requests_session):\n     r.raise_for_status()\n     data = r.json()\n     assert isinstance(data, list)\n+\n+\n+def test_recipe_history(conf, requests_session):\n+    r = requests_session.get(conf.getoption('server') + '/api/v1/recipe/')\n+    r.raise_for_status()\n+    data = r.json()\n+\n+    if len(data) == 0:\n+        pytest.skip('No recipes found.')\n+\n+    for item in data:\n+        endpoint = '/api/v1/recipe/{}/history/'.format(item['id'])\n+        r = requests_session.get(conf.getoption('server') + endpoint)\n+        r.raise_for_status()\n+        history = r.json()\n+\n+        last_date = datetime.now()\n+        for revision in history:\n+            created = datetime.strptime(revision)", "body_text": "I ran these tests against prod, and I got an error here:\n$ pytest contract-tests --server https://normandy.cdn.mozilla.net -vvv --tb=short\n...\ncontract-tests/test_api.py::test_recipe_history\ncontract-tests/test_api.py:137: in test_recipe_history\n    created = datetime.strptime(revision)\nE   TypeError: strptime() takes exactly 2 arguments (1 given)", "pull_request_url": "https://api.github.com/repos/mozilla/normandy/pulls/658", "url": "https://api.github.com/repos/mozilla/normandy/pulls/comments/110437018", "created_at": "2017-04-07T17:08:57Z", "author_association": "MEMBER", "body": "I ran these tests against prod, and I got an error here:\r\n\r\n```\r\n$ pytest contract-tests --server https://normandy.cdn.mozilla.net -vvv --tb=short\r\n...\r\ncontract-tests/test_api.py::test_recipe_history\r\ncontract-tests/test_api.py:137: in test_recipe_history\r\n    created = datetime.strptime(revision)\r\nE   TypeError: strptime() takes exactly 2 arguments (1 given)\r\n```", "updated_at": "2017-04-07T17:18:06Z", "html_url": "https://github.com/mozilla/normandy/pull/658#discussion_r110437018", "pull_request_review_id": 31611185, "_links": {"self": {"href": "https://api.github.com/repos/mozilla/normandy/pulls/comments/110437018"}, "html": {"href": "https://github.com/mozilla/normandy/pull/658#discussion_r110437018"}, "pull_request": {"href": "https://api.github.com/repos/mozilla/normandy/pulls/658"}}, "commit_id": "a666bb6e7d602f5bcac184ebb8717c8886104c41", "user": {"following_url": "https://api.github.com/users/mythmon/following{/other_user}", "events_url": "https://api.github.com/users/mythmon/events{/privacy}", "organizations_url": "https://api.github.com/users/mythmon/orgs", "url": "https://api.github.com/users/mythmon", "gists_url": "https://api.github.com/users/mythmon/gists{/gist_id}", "html_url": "https://github.com/mythmon", "subscriptions_url": "https://api.github.com/users/mythmon/subscriptions", "avatar_url": "https://avatars3.githubusercontent.com/u/305049?v=4", "repos_url": "https://api.github.com/users/mythmon/repos", "received_events_url": "https://api.github.com/users/mythmon/received_events", "gravatar_id": "", "starred_url": "https://api.github.com/users/mythmon/starred{/owner}{/repo}", "site_admin": false, "login": "mythmon", "type": "User", "id": 305049, "followers_url": "https://api.github.com/users/mythmon/followers"}, "position": null, "path": "recipe-server/contract-tests/test_api.py", "body_html": "<p>I ran these tests against prod, and I got an error here:</p>\n<pre><code>$ pytest contract-tests --server https://normandy.cdn.mozilla.net -vvv --tb=short\n...\ncontract-tests/test_api.py::test_recipe_history\ncontract-tests/test_api.py:137: in test_recipe_history\n    created = datetime.strptime(revision)\nE   TypeError: strptime() takes exactly 2 arguments (1 given)\n</code></pre>", "original_commit_id": "64f7d1108802773c9296e10c71b87e8b3c615d58", "id": 110437018}