{"original_position": 93, "diff_hunk": "@@ -174,13 +199,17 @@ this.RecipeRunner = {\n \n       try {\n         await manager.runAsyncCallback(\"postExecution\");\n+        Uptake.reportAction(actionName, Uptake.ACTION_SUCCESS);\n       } catch (err) {\n         log.info(`Could not run post-execution hook for ${actionName}:`, err.message);\n+        Uptake.reportAction(actionName, Uptake.ACTION_POST_EXECUTION_ERROR);\n       }\n     }\n \n     // Nuke sandboxes\n     Object.values(actionSandboxManagers).forEach(manager => manager.removeHold(\"recipeRunner\"));\n+\n+    Uptake.reportRunner(Uptake.RUNNER_SUCCESS);", "body_text": "This seems slightly surprising in that it reports success even when there were errors in parts of the execution. Is that intentional?", "pull_request_url": "https://api.github.com/repos/mozilla/normandy/pulls/818", "url": "https://api.github.com/repos/mozilla/normandy/pulls/comments/122926975", "created_at": "2017-06-20T09:38:04Z", "author_association": "CONTRIBUTOR", "body": "This seems slightly surprising in that it reports success even when there were errors in parts of the execution. Is that intentional?", "updated_at": "2017-07-21T16:50:57Z", "html_url": "https://github.com/mozilla/normandy/pull/818#discussion_r122926975", "pull_request_review_id": 45082071, "_links": {"self": {"href": "https://api.github.com/repos/mozilla/normandy/pulls/comments/122926975"}, "html": {"href": "https://github.com/mozilla/normandy/pull/818#discussion_r122926975"}, "pull_request": {"href": "https://api.github.com/repos/mozilla/normandy/pulls/818"}}, "commit_id": "93c2a45d817d55211a5aa0ea6379d3d9f8800a8b", "user": {"following_url": "https://api.github.com/users/gijsk/following{/other_user}", "events_url": "https://api.github.com/users/gijsk/events{/privacy}", "organizations_url": "https://api.github.com/users/gijsk/orgs", "url": "https://api.github.com/users/gijsk", "gists_url": "https://api.github.com/users/gijsk/gists{/gist_id}", "html_url": "https://github.com/gijsk", "subscriptions_url": "https://api.github.com/users/gijsk/subscriptions", "avatar_url": "https://avatars3.githubusercontent.com/u/375983?v=4", "repos_url": "https://api.github.com/users/gijsk/repos", "received_events_url": "https://api.github.com/users/gijsk/received_events", "gravatar_id": "", "starred_url": "https://api.github.com/users/gijsk/starred{/owner}{/repo}", "site_admin": false, "login": "gijsk", "type": "User", "id": 375983, "followers_url": "https://api.github.com/users/gijsk/followers"}, "position": null, "path": "recipe-client-addon/lib/RecipeRunner.jsm", "body_html": "<p>This seems slightly surprising in that it reports success even when there were errors in parts of the execution. Is that intentional?</p>", "original_commit_id": "260749b2fb00e039a207680482c91bc975ee972d", "id": 122926975}